<?xml version='1.0' encoding='utf-8'?>
<mujoco model="microduck">
  <compiler angle="radian" autolimits="true" />
  <worldbody>
    
    <body name="trunk_base" pos="0 0 0.12" quat="1 0 0 0">
      <freejoint name="trunk_base_freejoint" />
      <inertial pos="-0.0129858 -1.87297e-05 0.0210875" mass="0.26946" fullinertia="0.000253168 0.000342586 0.000212853 1.94331e-07 -4.04508e-05 1.06182e-07" />
      
      <site group="3" name="imu" pos="-0.0162825 0.00812245 0.06526" quat="1 0 0 -0" />
      
      <site group="3" name="torso_camera" pos="0.0506202 -0 0.0305024" quat="1 -0 -0 -0" />
      <body name="roll_motor_bottom" pos="0.0125202 0.02 0.0208" quat="0 0.707107 -0.707107 -0">
        
        <joint axis="0 0 1" name="left_hip_yaw" type="hinge" range="-0.5235987755982988 0.5235987755982988" />
        <inertial pos="0 -0.000243808 0.0205921" mass="0.0250187" fullinertia="5.56855e-06 5.01807e-06 2.44472e-06 0 -0 -1.8994e-08" />
        
        <body name="left_roll_to_pitch" pos="0 -0.01455 0.0286" quat="0 0 -0.707107 0.707107">
          
          <joint axis="0 0 1" name="left_hip_roll" type="hinge" range="-0.6981317007977362 0.6981317007977274" />
          <inertial pos="0.0359029 0.00016252 -0.0142127" mass="0.02709" fullinertia="4.61259e-06 7.88911e-06 5.4019e-06 7.4483e-08 4.8292e-08 1.1887e-08" />
          
          <body name="leg_plate" pos="0.0544 -0 -0.0245" quat="0.5 0.5 0.5 0.5">
            
            <joint axis="0 0 1" name="left_hip_pitch" type="hinge" range="-0.0 1.5707963267948966" />
            <inertial pos="-0.0298612 -0 -0.0142503" mass="0.0242215" fullinertia="3.15074e-06 6.26416e-06 5.11862e-06 0 2.0772e-08 -0" />
            
            <body name="leg_plate_2" pos="-0.042 -0 -0" quat="0.707107 -0 -0 -0.707107">
              
              <joint axis="0 0 1" name="left_knee" type="hinge" range="-1.9198621771937625 -0.0" />
              <inertial pos="0 -0.0305003 -0.0142358" mass="0.02326" fullinertia="5.9943e-06 3.01723e-06 4.77213e-06 -0 0 1.5359e-08" />
              
              <body name="foot" pos="-0 -0.042 0" quat="0 0 -0 -1">
                
                <joint axis="0 0 1" name="left_ankle" type="hinge" range="-1.5707963267948974 1.5707963267948957" />
                <inertial pos="0.00475687 0.0144058 -0.0145" mass="0.01474" fullinertia="2.49961e-06 5.27084e-06 3.79703e-06 -7.3107e-08 -1.8e-11 -6e-12" />
                
                <site group="3" name="left_foot" pos="0.0048 0.021 -0.0145" quat="0.707107 0.707107 0 0" />
              </body>
            </body>
          </body>
        </body>
      </body>
      
      <body name="long_neck_plate2" pos="0.0375202 0.0146 0.0552" quat="0 -0 0.707107 0.707107">
        
        <joint axis="0 0 1" name="neck_pitch" type="hinge" range="-1.2217304763960315 2.0943951023931944" />
        <inertial pos="-0.000824585 0.0446498 -0.0147264" mass="0.02714" fullinertia="9.79961e-06 3.73927e-06 8.13706e-06 -4.41738e-07 5.066e-09 3.9016e-08" />
        
        <body name="head_pitch_to_yaw" pos="0 0.06 -0" quat="1 -0 -0 0">
          
          <joint axis="0 0 1" name="head_pitch" type="hinge" range="-1.221730476396044 1.2217304763960173" />
          <inertial pos="0.00600297 0.0210515 -0.0145" mass="0.00677" fullinertia="2.34968e-06 1.22553e-06 2.0015e-06 -3.37269e-07 -0 0" />
          
          <body name="head_yaw_to_roll" pos="0 0.0465 -0.0145" quat="0 -0 -0.707107 0.707107">
            
            <joint axis="0 0 1" name="head_yaw" type="hinge" range="-2.6179938779914953 2.6179938779914935" />
            <inertial pos="0.00602348 0 0.0174917" mass="0.02914" fullinertia="4.9702e-06 1.03439e-05 1.03996e-05 0 6.69253e-07 0" />
            
            <body name="head_base_plate" pos="0.0305 -0 0.0145" quat="0.5 -0.5 0.5 -0.5">
              
              <joint axis="0 0 1" name="head_roll" type="hinge" range="-0.523598775598329 0.5235987755982686" />
              <inertial pos="0.00140986 -0.00204907 -0.0254714" mass="0.11807" fullinertia="0.000259694 0.000285092 7.12026e-05 -1.74595e-07 -6.40852e-06 9.72161e-06" />
              
              <site group="3" name="head_camera" pos="0 0.003 0.0394" quat="0.5 -0.5 -0.5 -0.5" />
              <site group="3" name="mouth_tip" pos="-0 -0.0175 0.0364" quat="0.5 -0.5 -0.5 -0.5" />
            </body>
          </body>
        </body>
      </body>
      
      <body name="xl330" pos="0.0125202 -0.02 0.0208" quat="0 -1 -0 -0">
        
        <joint axis="0 0 1" name="right_hip_yaw" type="hinge" range="-0.5235987755982988 0.5235987755982988" />
        <inertial pos="0.000243808 0 0.0205921" mass="0.0250187" fullinertia="5.01807e-06 5.56855e-06 2.44472e-06 -0 1.8994e-08 -0" />
        
        <body name="right_roll_to_pitch" pos="0.01455 0 0.0286" quat="0.5 -0.5 0.5 -0.5">
          
          <joint axis="0 0 1" name="right_hip_roll" type="hinge" range="-0.6981317007977336 0.69813170079773" />
          <inertial pos="-0.0359029 0.00016252 -0.0142127" mass="0.02709" fullinertia="4.61259e-06 7.88911e-06 5.4019e-06 -7.4483e-08 -4.8292e-08 1.1887e-08" />
          
          <body name="xl330_2" pos="-0.0544 0 -0.0245" quat="0.5 0.5 -0.5 -0.5">
            
            <joint axis="0 0 1" name="right_hip_pitch" type="hinge" range="-1.5707963267948877 8.881784197001252e-15" />
            <inertial pos="0.0305003 -0 -0.0142358" mass="0.02326" fullinertia="3.01723e-06 5.9943e-06 4.77213e-06 0 -1.5359e-08 0" />
            
            <body name="xl330_3" pos="0.042 -0 -0" quat="0.707107 0 0 0.707107">
              
              <joint axis="0 0 1" name="right_knee" type="hinge" range="-5.329070518200751e-15 1.9198621771937572" />
              <inertial pos="-0 -0.0305003 -0.0142358" mass="0.02326" fullinertia="5.9943e-06 3.01723e-06 4.77213e-06 0 0 1.5359e-08" />
              
              <body name="foot_2" pos="-0 -0.042 -0" quat="1 0 0 -0">
                
                <joint axis="0 0 1" name="right_ankle" type="hinge" range="-1.5707963267948983 1.5707963267948948" />
                <inertial pos="0.00475687 -0.0144058 -0.0145" mass="0.01474" fullinertia="2.49961e-06 5.27084e-06 3.79703e-06 7.3107e-08 1.8e-11 -6e-12" />
                
                <site group="3" name="right_foot" pos="0.0048 -0.021 -0.0145" quat="0.707107 -0.707107 -0 -0" />
              </body>
            </body>
          </body>
        </body>
      </body>
    </body>
  </worldbody>
  </mujoco>